INFO     run_all_uicase.py:test_login.py:86 开始执行脚本test_companyPassForget:

WARNING  urllib3.connectionpool:connectionpool.py:751 Retrying (Retry(total=2, connect=None, read=None, redirect=None, status=None)) after connection broken by 'NewConnectionError('<urllib3.connection.HTTPConnection object at 0x0000021769099250>: Failed to establish a new connection: [WinError 10061] 由于目标计算机积极拒绝，无法连接。')': /session/2359f84f3f6a39581c1a19ad5a68de6c/url
WARNING  urllib3.connectionpool:connectionpool.py:751 Retrying (Retry(total=1, connect=None, read=None, redirect=None, status=None)) after connection broken by 'NewConnectionError('<urllib3.connection.HTTPConnection object at 0x000002176912B4C0>: Failed to establish a new connection: [WinError 10061] 由于目标计算机积极拒绝，无法连接。')': /session/2359f84f3f6a39581c1a19ad5a68de6c/url
WARNING  urllib3.connectionpool:connectionpool.py:751 Retrying (Retry(total=0, connect=None, read=None, redirect=None, status=None)) after connection broken by 'NewConnectionError('<urllib3.connection.HTTPConnection object at 0x000002176912BF10>: Failed to establish a new connection: [WinError 10061] 由于目标计算机积极拒绝，无法连接。')': /session/2359f84f3f6a39581c1a19ad5a68de6c/url