INFO     run_all_uicase.py:test_backStage_authentication.py:72 开始执行脚本test_backStage_authentication:

INFO     run_all_uicase.py:test_backStage_authentication.py:75 开始执行脚本test_backStage_authentication:

INFO     run_all_uicase.py:test_login.py:113 成功进入到密码重置页面
INFO     run_all_uicase.py:test_login.py:122 成功进入到密码修改完成页面
WARNING  urllib3.connectionpool:connectionpool.py:751 Retrying (Retry(total=2, connect=None, read=None, redirect=None, status=None)) after connection broken by 'NewConnectionError('<urllib3.connection.HTTPConnection object at 0x000001D4C1703190>: Failed to establish a new connection: [WinError 10061] 由于目标计算机积极拒绝，无法连接。')': /session/6225f2004bac5a80f367834124c19427/element
WARNING  urllib3.connectionpool:connectionpool.py:751 Retrying (Retry(total=1, connect=None, read=None, redirect=None, status=None)) after connection broken by 'NewConnectionError('<urllib3.connection.HTTPConnection object at 0x000001D4C17473D0>: Failed to establish a new connection: [WinError 10061] 由于目标计算机积极拒绝，无法连接。')': /session/6225f2004bac5a80f367834124c19427/element
WARNING  urllib3.connectionpool:connectionpool.py:751 Retrying (Retry(total=0, connect=None, read=None, redirect=None, status=None)) after connection broken by 'NewConnectionError('<urllib3.connection.HTTPConnection object at 0x000001D4C1754070>: Failed to establish a new connection: [WinError 10061] 由于目标计算机积极拒绝，无法连接。')': /session/6225f2004bac5a80f367834124c19427/element