INFO     run_all_uicase.py:test_login.py:29 开始执行脚本test_companyLoginOn:

WARNING  urllib3.connectionpool:connectionpool.py:751 Retrying (Retry(total=2, connect=None, read=None, redirect=None, status=None)) after connection broken by 'NewConnectionError('<urllib3.connection.HTTPConnection object at 0x0000022B83463700>: Failed to establish a new connection: [WinError 10061] 由于目标计算机积极拒绝，无法连接。')': /session/13fdb19841c552dd88a7a784b30d1eac/url
WARNING  urllib3.connectionpool:connectionpool.py:751 Retrying (Retry(total=1, connect=None, read=None, redirect=None, status=None)) after connection broken by 'NewConnectionError('<urllib3.connection.HTTPConnection object at 0x0000022B83217D30>: Failed to establish a new connection: [WinError 10061] 由于目标计算机积极拒绝，无法连接。')': /session/13fdb19841c552dd88a7a784b30d1eac/url
WARNING  urllib3.connectionpool:connectionpool.py:751 Retrying (Retry(total=0, connect=None, read=None, redirect=None, status=None)) after connection broken by 'NewConnectionError('<urllib3.connection.HTTPConnection object at 0x0000022B83217070>: Failed to establish a new connection: [WinError 10061] 由于目标计算机积极拒绝，无法连接。')': /session/13fdb19841c552dd88a7a784b30d1eac/url