INFO     run_all_uicase.py:test_login.py:29 开始执行脚本test_companyLoginOn:

WARNING  urllib3.connectionpool:connectionpool.py:751 Retrying (Retry(total=2, connect=None, read=None, redirect=None, status=None)) after connection broken by 'NewConnectionError('<urllib3.connection.HTTPConnection object at 0x000001A119A9CD00>: Failed to establish a new connection: [WinError 10061] 由于目标计算机积极拒绝，无法连接。')': /session/4127c27a1dbb925702bd3ed3c043ae02/url
WARNING  urllib3.connectionpool:connectionpool.py:751 Retrying (Retry(total=1, connect=None, read=None, redirect=None, status=None)) after connection broken by 'NewConnectionError('<urllib3.connection.HTTPConnection object at 0x000001A119B98040>: Failed to establish a new connection: [WinError 10061] 由于目标计算机积极拒绝，无法连接。')': /session/4127c27a1dbb925702bd3ed3c043ae02/url
WARNING  urllib3.connectionpool:connectionpool.py:751 Retrying (Retry(total=0, connect=None, read=None, redirect=None, status=None)) after connection broken by 'NewConnectionError('<urllib3.connection.HTTPConnection object at 0x000001A119B981F0>: Failed to establish a new connection: [WinError 10061] 由于目标计算机积极拒绝，无法连接。')': /session/4127c27a1dbb925702bd3ed3c043ae02/url