Thu, 24 Sep 2020 16:59:59-run_all_case.py-test_api_per.py-[line:30]-INFO-[日志信息]: 开始执行脚本<module>:

Exception in thread Thread-1:
Traceback (most recent call last):
  File "C:\Users\shaojunshuai\AppData\Local\Programs\Python\Python36\lib\site-packages\urllib3\connectionpool.py", line 677, in urlopen
    chunked=chunked,
  File "C:\Users\shaojunshuai\AppData\Local\Programs\Python\Python36\lib\site-packages\urllib3\connectionpool.py", line 426, in _make_request
    six.raise_from(e, None)
  File "<string>", line 3, in raise_from
  File "C:\Users\shaojunshuai\AppData\Local\Programs\Python\Python36\lib\site-packages\urllib3\connectionpool.py", line 421, in _make_request
    httplib_response = conn.getresponse()
  File "C:\Users\shaojunshuai\AppData\Local\Programs\Python\Python36\lib\http\client.py", line 1331, in getresponse
    response.begin()
  File "C:\Users\shaojunshuai\AppData\Local\Programs\Python\Python36\lib\http\client.py", line 297, in begin
    version, status, reason = self._read_status()
  File "C:\Users\shaojunshuai\AppData\Local\Programs\Python\Python36\lib\http\client.py", line 258, in _read_status
    line = str(self.fp.readline(_MAXLINE + 1), "iso-8859-1")
  File "C:\Users\shaojunshuai\AppData\Local\Programs\Python\Python36\lib\socket.py", line 586, in readinto
    return self._sock.recv_into(b)
TimeoutError: [WinError 10060] 由于连接方在一段时间后没有正确答复或连接的主机没有反应，连接尝试失败。

During handling of the above exception, another exception occurred:

Traceback (most recent call last):
  File "C:\Users\shaojunshuai\AppData\Local\Programs\Python\Python36\lib\site-packages\requests\adapters.py", line 449, in send
    timeout=timeout
  File "C:\Users\shaojunshuai\AppData\Local\Programs\Python\Python36\lib\site-packages\urllib3\connectionpool.py", line 727, in urlopen
    method, url, error=e, _pool=self, _stacktrace=sys.exc_info()[2]
  File "C:\Users\shaojunshuai\AppData\Local\Programs\Python\Python36\lib\site-packages\urllib3\util\retry.py", line 403, in increment
    raise six.reraise(type(error), error, _stacktrace)
  File "C:\Users\shaojunshuai\AppData\Local\Programs\Python\Python36\lib\site-packages\urllib3\packages\six.py", line 734, in reraise
    raise value.with_traceback(tb)
  File "C:\Users\shaojunshuai\AppData\Local\Programs\Python\Python36\lib\site-packages\urllib3\connectionpool.py", line 677, in urlopen
    chunked=chunked,
  File "C:\Users\shaojunshuai\AppData\Local\Programs\Python\Python36\lib\site-packages\urllib3\connectionpool.py", line 426, in _make_request
    six.raise_from(e, None)
  File "<string>", line 3, in raise_from
  File "C:\Users\shaojunshuai\AppData\Local\Programs\Python\Python36\lib\site-packages\urllib3\connectionpool.py", line 421, in _make_request
    httplib_response = conn.getresponse()
  File "C:\Users\shaojunshuai\AppData\Local\Programs\Python\Python36\lib\http\client.py", line 1331, in getresponse
    response.begin()
  File "C:\Users\shaojunshuai\AppData\Local\Programs\Python\Python36\lib\http\client.py", line 297, in begin
    version, status, reason = self._read_status()
  File "C:\Users\shaojunshuai\AppData\Local\Programs\Python\Python36\lib\http\client.py", line 258, in _read_status
    line = str(self.fp.readline(_MAXLINE + 1), "iso-8859-1")
  File "C:\Users\shaojunshuai\AppData\Local\Programs\Python\Python36\lib\socket.py", line 586, in readinto
    return self._sock.recv_into(b)
urllib3.exceptions.ProtocolError: ('Connection aborted.', TimeoutError(10060, '由于连接方在一段时间后没有正确答复或连接的主机没有反应，连接尝试失败。', None, 10060, None))

During handling of the above exception, another exception occurred:

Traceback (most recent call last):
  File "C:\Users\shaojunshuai\AppData\Local\Programs\Python\Python36\lib\threading.py", line 916, in _bootstrap_inner
    self.run()
  File "C:\Users\shaojunshuai\AppData\Local\Programs\Python\Python36\lib\threading.py", line 1182, in run
    self.function(*self.args, **self.kwargs)
  File "C:\Users\shaojunshuai\PycharmProjects\AutoTest-python\Auto_Test\test_case\test_Api_demo\test_api_per.py", line 46, in fun_ApiTimeLoop
    opera_result = RequestsHandler().post_Req(url=opera_url, params='')
  File "C:\Users\shaojunshuai\PycharmProjects\AutoTest-python\Auto_Test\common\Request.py", line 33, in post_Req
    res = requests.post(url, data=data, json=json, **kw)  # 其中data是form表单形式的
  File "C:\Users\shaojunshuai\AppData\Local\Programs\Python\Python36\lib\site-packages\requests\api.py", line 119, in post
    return request('post', url, data=data, json=json, **kwargs)
  File "C:\Users\shaojunshuai\AppData\Local\Programs\Python\Python36\lib\site-packages\requests\api.py", line 61, in request
    return session.request(method=method, url=url, **kwargs)
  File "C:\Users\shaojunshuai\AppData\Local\Programs\Python\Python36\lib\site-packages\requests\sessions.py", line 530, in request
    resp = self.send(prep, **send_kwargs)
  File "C:\Users\shaojunshuai\AppData\Local\Programs\Python\Python36\lib\site-packages\requests\sessions.py", line 643, in send
    r = adapter.send(request, **kwargs)
  File "C:\Users\shaojunshuai\AppData\Local\Programs\Python\Python36\lib\site-packages\requests\adapters.py", line 498, in send
    raise ConnectionError(err, request=request)
requests.exceptions.ConnectionError: ('Connection aborted.', TimeoutError(10060, '由于连接方在一段时间后没有正确答复或连接的主机没有反应，连接尝试失败。', None, 10060, None))

